<?xml version="1.0" ?>
<robot name="sphere_hand_floating">
  <link name="world"/>
  <link name="base_world"/>
  <link name="base_px">
    <inertial>
        <origin rpy="0 0 0" xyz="0 0 0"/>
      <mass value="2"/>
      <inertia ixx="0.1" ixy="0" ixz="0" iyy="0.1" iyz="0" izz="0.1"/>
    </inertial>
  </link>
  <link name="base_py">
    <inertial>
        <origin rpy="0 0 0" xyz="0 0 0"/>
      <mass value="2"/>
      <inertia ixx="0.1" ixy="0" ixz="0" iyy="0.1" iyz="0" izz="0.1"/>
    </inertial>
  </link>
  <link name="base_pz">
    <inertial>
        <origin rpy="0 0 0" xyz="0 0 0"/>
      <mass value="2"/>
      <inertia ixx="0.1" ixy="0" ixz="0" iyy="0.1" iyz="0" izz="0.1"/>
    </inertial>
  </link>
  <joint name="base_world_joint" type="fixed">
    <parent link="world"/>
    <child link="base_world"/>
    <origin rpy="0 0 0" xyz="0 0 0"/>
  </joint>
  <joint name="base_joint_pris_x" type="prismatic">
    <parent link="base_world"/>
    <child link="base_px"/>
    <origin rpy="0 0 0" xyz="0 0 0"/>
    <axis xyz="1 0 0"/>
    <limit effort="1e6" lower="-6.28" upper="6.28" velocity="6.28"/>
  </joint>
  <joint name="base_joint_pris_y" type="prismatic">
    <parent link="base_px"/>
    <child link="base_py"/>
    <origin rpy="0 0 0" xyz="0 0 0"/>
    <axis xyz="0 1 0"/>
    <limit effort="1e6" lower="-6.28" upper="6.28" velocity="6.28"/>
  </joint>
  <joint name="base_joint_pris_z" type="prismatic">
    <parent link="base_py"/>
    <child link="base_pz"/>
    <origin rpy="0 0 0" xyz="0 0 0"/>
    <axis xyz="0 0 1"/>
    <limit effort="1e6" lower="-6.28" upper="6.28" velocity="6.28"/>
  </joint>
  <joint name="hand_base_joint" type="fixed">
    <parent link="base_pz"/>
    <child link="hand_base_link"/>
    <origin rpy="0 0 0" xyz="0 0 0"/>
  </joint> 
  <link name="hand_base_link">
    <inertial>
        <origin rpy="0 0 0" xyz="0 0 0"/>
        <mass value="0.0"/>
        <inertia ixx="0.0" ixy="0" ixz="0" iyy="0.0" iyz="0" izz="0.0"/>
    </inertial>
  </link>
  <joint name="sphere_hand_joint" type="fixed">
    <parent link="hand_base_link"/>
    <child link="sphere_hand"/>
    <origin rpy="0 0 0.0" xyz="0 0 0"/>
    <!-- <origin rpy="0 0 -0.785398163397" xyz="0 0 0"/> -->
  </joint>
  <link name="sphere_hand">
    <inertial>
      <origin rpy="0 0 0" xyz="0 0 0.04"/>
       <mass value=".81"/>
       <inertia ixx="0.1" ixy="0" ixz="0" iyy="0.1" iyz="0" izz="0.1"/>
    </inertial>
    <visual>
      <geometry>
        <sphere radius="0.1"/>
      </geometry>
      <material name="panda_white"/>
    </visual>
    <collision>
      <geometry>
        <sphere radius="0.1"/>
      </geometry>
      <material name="panda_white"/>
    </collision>
  </link>
  <link name="sphere_target">
    <inertial>
      <origin rpy="0 0 0" xyz="0 0 0"/>
      <mass value="0.0"/>
      <inertia ixx="0.1" ixy="0" ixz="0" iyy="0.1" iyz="0" izz="0.1"/>
    </inertial>
  </link>
  <joint name="sphere_target_joint" type="fixed">
    <parent link="sphere_hand"/>
    <child link="sphere_target"/>
    <origin rpy="0 0 0" xyz="0 0 0"/>
  </joint>
</robot>
