<?xml version="1.0" ?>
<robot name="panda_hand_floating">
  <link name="world"/>
  <link name="base_world"/>
  <link name="base_px">
    <inertial>
        <origin rpy="0 0 0" xyz="0 0 0"/>
      <mass value="2"/>
      <inertia ixx="0.1" ixy="0" ixz="0" iyy="0.1" iyz="0" izz="0.1"/>
    </inertial>
  </link>
  <link name="base_py">
    <inertial>
        <origin rpy="0 0 0" xyz="0 0 0"/>
      <mass value="2"/>
      <inertia ixx="0.1" ixy="0" ixz="0" iyy="0.1" iyz="0" izz="0.1"/>
    </inertial>
  </link>
  <link name="base_pz">
    <inertial>
        <origin rpy="0 0 0" xyz="0 0 0"/>
      <mass value="2"/>
      <inertia ixx="0.1" ixy="0" ixz="0" iyy="0.1" iyz="0" izz="0.1"/>
    </inertial>
  </link>
  <link name="base_rx">
    <inertial>
        <origin rpy="0 0 0" xyz="0 0 0"/>
      <mass value="2"/>
      <inertia ixx="0.1" ixy="0" ixz="0" iyy="0.1" iyz="0" izz="0.1"/>
    </inertial>
  </link>
  <link name="base_ry">
    <inertial>
        <origin rpy="0 0 0" xyz="0 0 0"/>
      <mass value="2"/>
      <inertia ixx="0.1" ixy="0" ixz="0" iyy="0.1" iyz="0" izz="0.1"/>
    </inertial>
  </link>
  <link name="base_rz">
    <inertial>
        <origin rpy="0 0 0" xyz="0 0 0"/>
      <mass value="2"/>
      <inertia ixx="0.1" ixy="0" ixz="0" iyy="0.1" iyz="0" izz="0.1"/>
    </inertial>
  </link>
  <joint name="base_world_joint" type="fixed">
    <parent link="world"/>
    <child link="base_world"/>
    <origin rpy="0 0 0" xyz="0 0 0"/>
  </joint>
  <joint name="base_joint_pris_x" type="prismatic">
    <parent link="base_world"/>
    <child link="base_px"/>
    <origin rpy="0 0 0" xyz="0 0 0"/>
    <axis xyz="1 0 0"/>
    <limit effort="1e6" lower="-6.28" upper="6.28" velocity="6.28"/>
  </joint>
  <joint name="base_joint_pris_y" type="prismatic">
    <parent link="base_px"/>
    <child link="base_py"/>
    <origin rpy="0 0 0" xyz="0 0 0"/>
    <axis xyz="0 1 0"/>
    <limit effort="1e6" lower="-6.28" upper="6.28" velocity="6.28"/>
  </joint>
  <joint name="base_joint_pris_z" type="prismatic">
    <parent link="base_py"/>
    <child link="base_pz"/>
    <origin rpy="0 0 0" xyz="0 0 0"/>
    <axis xyz="0 0 1"/>
    <limit effort="1e6" lower="-6.28" upper="6.28" velocity="6.28"/>
  </joint>
  <joint name="base_joint_rev_x" type="continuous">
    <parent link="base_pz"/>
    <child link="base_rx"/>
    <origin rpy="0 0 0" xyz="0 0 0"/>
    <axis xyz="1 0 0"/>
    <limit effort="1e6" lower="-100" upper="100" velocity="6.28"/>
  </joint>
  <joint name="base_joint_rev_y" type="continuous">
    <parent link="base_rx"/>
    <child link="base_ry"/>
    <origin rpy="0 0 0" xyz="0 0 0"/>
    <axis xyz="0 1 0"/>
    <limit effort="1e6" lower="-100" upper="100" velocity="6.28"/>
  </joint>
  <joint name="base_joint_rev_z" type="continuous">
    <parent link="base_ry"/>
    <child link="base_rz"/>
    <origin rpy="0 0 0" xyz="0 0 0"/>
    <axis xyz="0 0 1"/>
    <limit effort="1e6" lower="-100" upper="100" velocity="6.28"/>
  </joint>
  <joint name="hand_base_joint" type="fixed">
    <parent link="base_rz"/>
    <child link="hand_base_link"/>
    <origin rpy="0 0 0" xyz="0 0 0"/>
  </joint> 
  <link name="hand_base_link">
    <inertial>
        <origin rpy="0 0 0" xyz="0 0 0"/>
        <mass value="0.0"/>
        <inertia ixx="0.0" ixy="0" ixz="0" iyy="0.0" iyz="0" izz="0.0"/>
    </inertial>
  </link>
  <joint name="panda_hand_joint" type="fixed">
    <parent link="hand_base_link"/>
    <child link="robotiq_arg2f_coupling"/>
    <origin rpy="0 0 3.1415" xyz="0 0 0"/>
  </joint>
    <link name="robotiq_arg2f_coupling">
        <inertial>
            <origin rpy="0 0 0" xyz="0 0 0"/>
            <mass value="0.05"/>
            <inertia ixx="2E-06" ixy="-4E-10" ixz="-2E-10" iyy="2E-06" iyz="-3E-08" izz="2E-06"/>
        </inertial>
        <visual>
            <origin rpy="0 0 0" xyz="0 0 0"/>
            <geometry>
                <mesh filename="meshes/robotiq_2f140/visual/robotiq_arg2f_coupling.obj" scale="0.001 0.001 0.001"/>
            </geometry>
            <material name="">
                <color rgba="0.1 0.1 0.1 1"/>
            </material>
        </visual>
        <collision>
            <origin rpy="0 0 0" xyz="0 0 0"/>
            <geometry>
                <mesh filename="meshes/robotiq_2f140/collision/robotiq_arg2f_coupling.obj" scale="0.001 0.001 0.001"/>
            </geometry>
        </collision>
    </link>
    <link name="robotiq_arg2f_base_link">
        <inertial>
            <origin rpy="0 0 0" xyz="8.625E-08 -4.6583E-06 0.03145"/>
            <mass value="0.22652"/>
            <inertia ixx="0.00020005" ixy="-4.2442E-10" ixz="-2.9069E-10" iyy="0.00017832" iyz="-3.4402E-08"
                     izz="0.00013478"/>
        </inertial>
        <visual>
            <origin rpy="0 0 0" xyz="0 0 0"/>
            <geometry>
                <mesh filename="meshes/robotiq_2f140/visual/robotiq_arg2f_base_link.obj"/>
            </geometry>
            <material name="">
                <color rgba="0.1 0.1 0.1 1"/>
            </material>
        </visual>
        <collision>
            <origin rpy="0 0 0" xyz="0 0 0"/>
            <geometry>
                <mesh filename="meshes/robotiq_2f140/collision/robotiq_arg2f_base_link.obj"/>
            </geometry>
        </collision>
    </link>
    <link name="left_outer_knuckle">
        <inertial>
            <origin rpy="0 0 0" xyz="-0.000200000000003065 0.0199435877845359 0.0292245259211331"/>
            <mass value="0.00853198276973456"/>
            <inertia ixx="2.89328108496468E-06" ixy="-1.57935047237397E-19" ixz="-1.93980378593255E-19"
                     iyy="1.86719750325683E-06" iyz="-1.21858577871576E-06" izz="1.21905238907251E-06"/>
        </inertial>
        <visual>
            <origin rpy="0 0 0" xyz="0 0 0"/>
            <geometry>
                <mesh filename="meshes/robotiq_2f140/visual/robotiq_arg2f_140_outer_knuckle.obj"/>
            </geometry>
            <material name="">
                <color rgba="0.792156862745098 0.819607843137255 0.933333333333333 1"/>
            </material>
        </visual>
        <collision>
            <origin rpy="0 0 0" xyz="0 0 0"/>
            <geometry>
                <mesh filename="meshes/robotiq_2f140/collision/robotiq_arg2f_140_outer_knuckle.obj"/>
            </geometry>
        </collision>
    </link>
    <link name="left_outer_finger">
        <inertial>
            <origin rpy="0 0 0" xyz="0.00030115855001899 0.0373907951953854 -0.0208027427000385"/>
            <mass value="0.022614240507152"/>
            <inertia ixx="1.52518312458174E-05" ixy="9.76583423954399E-10" ixz="-5.43838577022588E-10"
                     iyy="6.17694243867776E-06" iyz="6.78636130740228E-06" izz="1.16494917907219E-05"/>
        </inertial>
        <visual>
            <origin rpy="0 0 0" xyz="0 0 0"/>
            <geometry>
                <mesh filename="meshes/robotiq_2f140/visual/robotiq_arg2f_140_outer_finger.obj"/>
            </geometry>
            <material name="">
                <color rgba="0.1 0.1 0.1 1"/>
            </material>
        </visual>
        <collision>
            <origin rpy="0 0 0" xyz="0 0 0"/>
            <geometry>
                <mesh filename="meshes/robotiq_2f140/collision/robotiq_arg2f_140_outer_finger.obj"/>
            </geometry>
        </collision>
    </link>
    <link name="left_inner_finger">
        <inertial>
            <origin rpy="0 0 0" xyz="0.000299999999999317 0.0160078233491243 -0.0136945669206257"/>
            <mass value="0.0104003125914103"/>
            <inertia ixx="2.71909453810972E-06" ixy="1.35402465472579E-21" ixz="-7.1817349065269E-22"
                     iyy="7.69100314106116E-07" iyz="6.74715432769696E-07" izz="2.30315190420171E-06"/>
        </inertial>
        <visual>
            <origin rpy="0 0 0" xyz="0 0 0"/>
            <geometry>
                <mesh filename="meshes/robotiq_2f140/visual/robotiq_arg2f_140_inner_finger.obj"/>
            </geometry>
            <material name="">
                <color rgba="0.1 0.1 0.1 1"/>
            </material>
        </visual>
        <collision>
            <origin rpy="0 0 0" xyz="0 0 0"/>
            <geometry>
                <mesh filename="meshes/robotiq_2f140/collision/robotiq_arg2f_140_inner_finger.obj"/>
            </geometry>
        </collision>
    </link>
    <link name="left_inner_finger_pad">
        <visual>
            <origin rpy="0 0 0" xyz="0 0 0"/>
            <geometry>
                <box size="0.027 0.065 0.0075"/>
            </geometry>
            <material name="">
                <color rgba="0.9 0.9 0.9 1"/>
            </material>
        </visual>
        <collision>
            <origin rpy="0 0 0" xyz="0 0 0"/>
            <geometry>
                <box size="0.03 0.07 0.0075"/>
            </geometry>
            <material name="">
                <color rgba="0.9 0.0 0.0 1"/>
            </material>
        </collision>
    </link>
    <link name="left_inner_knuckle">
        <inertial>
            <origin rpy="0 0 0" xyz="0.000123011831763771 0.0507850843201817 0.00103968640075166"/>
            <mass value="0.0271177346495152"/>
            <inertia ixx="2.61910379223783E-05" ixy="-2.43616858946494E-07" ixz="-6.37789906117123E-09"
                     iyy="2.8270243746167E-06" iyz="-5.37200748039765E-07" izz="2.83695868220296E-05"/>
        </inertial>
        <visual>
            <origin rpy="0 0 0" xyz="0 0 0"/>
            <geometry>
                <mesh filename="meshes/robotiq_2f140/visual/robotiq_arg2f_140_inner_knuckle.obj"/>
            </geometry>
            <material name="">
                <color rgba="0.1 0.1 0.1 1"/>
            </material>
        </visual>
        <collision>
            <origin rpy="0 0 0" xyz="0 0 0"/>
            <geometry>
                <mesh filename="meshes/robotiq_2f140/collision/robotiq_arg2f_140_inner_knuckle.obj"/>
            </geometry>
        </collision>
    </link>
    <link name="right_outer_knuckle">
        <inertial>
            <origin rpy="0 0 0" xyz="-0.000200000000003065 0.0199435877845359 0.0292245259211331"/>
            <mass value="0.00853198276973456"/>
            <inertia ixx="2.89328108496468E-06" ixy="-1.57935047237397E-19" ixz="-1.93980378593255E-19"
                     iyy="1.86719750325683E-06" iyz="-1.21858577871576E-06" izz="1.21905238907251E-06"/>
        </inertial>
        <visual>
            <origin rpy="0 0 0" xyz="0 0 0"/>
            <geometry>
                <mesh filename="meshes/robotiq_2f140/visual/robotiq_arg2f_140_outer_knuckle.obj"/>
            </geometry>
            <material name="">
                <color rgba="0.792156862745098 0.819607843137255 0.933333333333333 1"/>
            </material>
        </visual>
        <collision>
            <origin rpy="0 0 0" xyz="0 0 0"/>
            <geometry>
                <mesh filename="meshes/robotiq_2f140/collision/robotiq_arg2f_140_outer_knuckle.obj"/>
            </geometry>
        </collision>
    </link>
    <link name="right_outer_finger">
        <inertial>
            <origin rpy="0 0 0" xyz="0.00030115855001899 0.0373907951953854 -0.0208027427000385"/>
            <mass value="0.022614240507152"/>
            <inertia ixx="1.52518312458174E-05" ixy="9.76583423954399E-10" ixz="-5.43838577022588E-10"
                     iyy="6.17694243867776E-06" iyz="6.78636130740228E-06" izz="1.16494917907219E-05"/>
        </inertial>
        <visual>
            <origin rpy="0 0 0" xyz="0 0 0"/>
            <geometry>
                <mesh filename="meshes/robotiq_2f140/visual/robotiq_arg2f_140_outer_finger.obj"/>
            </geometry>
            <material name="">
                <color rgba="0.1 0.1 0.1 1"/>
            </material>
        </visual>
        <collision>
            <origin rpy="0 0 0" xyz="0 0 0"/>
            <geometry>
                <mesh filename="meshes/robotiq_2f140/collision/robotiq_arg2f_140_outer_finger.obj"/>
            </geometry>
        </collision>
    </link>
    <link name="right_inner_finger">
        <inertial>
            <origin rpy="0 0 0" xyz="0.000299999999999317 0.0160078233491243 -0.0136945669206257"/>
            <mass value="0.0104003125914103"/>
            <inertia ixx="2.71909453810972E-06" ixy="1.35402465472579E-21" ixz="-7.1817349065269E-22"
                     iyy="7.69100314106116E-07" iyz="6.74715432769696E-07" izz="2.30315190420171E-06"/>
        </inertial>
        <visual>
            <origin rpy="0 0 0" xyz="0 0 0"/>
            <geometry>
                <mesh filename="meshes/robotiq_2f140/visual/robotiq_arg2f_140_inner_finger.obj"/>
            </geometry>
            <material name="">
                <color rgba="0.1 0.1 0.1 1"/>
            </material>
        </visual>
        <collision>
            <origin rpy="0 0 0" xyz="0 0 0"/>
            <geometry>
                <mesh filename="meshes/robotiq_2f140/collision/robotiq_arg2f_140_inner_finger.obj"/>
            </geometry>
        </collision>
    </link>
    <link name="right_inner_finger_pad">
        <visual>
            <origin rpy="0 0 0" xyz="0 0 0"/>
            <geometry>
                <box size="0.027 0.065 0.0075"/>
            </geometry>
            <material name="">
                <color rgba="0.9 0.9 0.9 1"/>
            </material>
        </visual>
        <collision>
            <origin rpy="0 0 0" xyz="0 0 0"/>
            <geometry>
                <box size="0.03 0.07 0.0075"/>
            </geometry>
            <material name="">
                <color rgba="0.9 0.0 0.0 1"/>
            </material>
        </collision>
    </link>
    <link name="right_inner_knuckle">
        <inertial>
            <origin rpy="0 0 0" xyz="0.000123011831763771 0.0507850843201817 0.00103968640075166"/>
            <mass value="0.0271177346495152"/>
            <inertia ixx="2.61910379223783E-05" ixy="-2.43616858946494E-07" ixz="-6.37789906117123E-09"
                     iyy="2.8270243746167E-06" iyz="-5.37200748039765E-07" izz="2.83695868220296E-05"/>
        </inertial>
        <visual>
            <origin rpy="0 0 0" xyz="0 0 0"/>
            <geometry>
                <mesh filename="meshes/robotiq_2f140/visual/robotiq_arg2f_140_inner_knuckle.obj"/>
            </geometry>
            <material name="">
                <color rgba="0.1 0.1 0.1 1"/>
            </material>
        </visual>
        <collision>
            <origin rpy="0 0 0" xyz="0 0 0"/>
            <geometry>
                <mesh filename="meshes/robotiq_2f140/collision/robotiq_arg2f_140_inner_knuckle.obj"/>
            </geometry>
        </collision>
    </link>
    <joint name="finger_joint" type="revolute">
        <origin rpy="2.29579632679 0 0" xyz="0 -0.030601 0.054905"/>
        <parent link="robotiq_arg2f_base_link"/>
        <child link="left_outer_knuckle"/>
        <axis xyz="-1 0 0"/>
        <limit effort="1000" lower="0" upper="0.7" velocity="2.0"/>
    </joint>
    <joint name="left_outer_finger_joint" type="fixed">
        <origin rpy="0 0 0" xyz="0 0.01821998610742 0.0260018192872234"/>
        <parent link="left_outer_knuckle"/>
        <child link="left_outer_finger"/>
        <axis xyz="1 0 0"/>
    </joint>
    <joint name="left_inner_knuckle_joint" type="revolute">
        <origin rpy="2.29579632679 0 0.0" xyz="0 -0.0127 0.06142"/>
        <parent link="robotiq_arg2f_base_link"/>
        <child link="left_inner_knuckle"/>
        <axis xyz="1 0 0"/>
        <limit effort="1000" lower="-0.8757" upper="0.8757" velocity="2.0"/>
        <mimic joint="finger_joint" multiplier="-1" offset="0"/>
    </joint>
    <joint name="left_inner_finger_joint" type="revolute">
        <origin rpy="-0.725 0 0" xyz="0 0.0817554015893473 -0.0282203446692936"/>
        <parent link="left_outer_finger"/>
        <child link="left_inner_finger"/>
        <axis xyz="1 0 0"/>
        <limit effort="1000" lower="-0.8757" upper="0.8757" velocity="2.0"/>
        <mimic joint="finger_joint" multiplier="1" offset="0"/>
    </joint>
    <joint name="left_inner_finger_pad_joint" type="fixed">
        <origin rpy="0 0 0" xyz="0 0.0457554015893473 -0.0272203446692936"/>
        <parent link="left_inner_finger"/>
        <child link="left_inner_finger_pad"/>
        <axis xyz="0 0 1"/>
    </joint>
    <joint name="right_outer_knuckle_joint" type="revolute">
        <origin rpy="2.29579632679 0 3.14159265359" xyz="0 0.030601 0.054905"/>
        <parent link="robotiq_arg2f_base_link"/>
        <child link="right_outer_knuckle"/>
        <axis xyz="1 0 0"/>
        <limit effort="1000" lower="-0.725" upper="0.725" velocity="2.0"/>
        <mimic joint="finger_joint" multiplier="-1" offset="0"/>
    </joint>
    <joint name="right_outer_finger_joint" type="fixed">
        <origin rpy="0 0 0" xyz="0 0.01821998610742 0.0260018192872234"/>
        <parent link="right_outer_knuckle"/>
        <child link="right_outer_finger"/>
        <axis xyz="1 0 0"/>
    </joint>
    <joint name="right_inner_knuckle_joint" type="revolute">
        <origin rpy="2.29579632679 0 -3.14159265359" xyz="0 0.0127 0.06142"/>
        <parent link="robotiq_arg2f_base_link"/>
        <child link="right_inner_knuckle"/>
        <axis xyz="1 0 0"/>
        <limit effort="1000" lower="-0.8757" upper="0.8757" velocity="2.0"/>
        <mimic joint="finger_joint" multiplier="-1" offset="0"/>
    </joint>
    <joint name="right_inner_finger_joint" type="revolute">
        <origin rpy="-0.725 0 0" xyz="0 0.0817554015893473 -0.0282203446692936"/>
        <parent link="right_outer_finger"/>
        <child link="right_inner_finger"/>
        <axis xyz="1 0 0"/>
        <limit effort="1000" lower="-0.8757" upper="0.8757" velocity="2.0"/>
        <mimic joint="finger_joint" multiplier="1" offset="0"/>
    </joint>
    <joint name="right_inner_finger_pad_joint" type="fixed">
        <origin rpy="0 0 0" xyz="0 0.0457554015893473 -0.0272203446692936"/>
        <parent link="right_inner_finger"/>
        <child link="right_inner_finger_pad"/>
        <axis xyz="0 0 1"/>
    </joint>
    <transmission name="finger_joint_trans">
        <type>transmission_interface/SimpleTransmission</type>
        <joint name="finger_joint">
            <hardwareInterface>hardware_interface/PositionJointInterface</hardwareInterface>
        </joint>
        <actuator name="finger_joint_motor">
            <mechanicalReduction>1</mechanicalReduction>
        </actuator>
    </transmission>
    <gazebo>
        <!-- loading plugin: mimic joints works in gazebo now-->
        <plugin filename="libroboticsgroup_gazebo_mimic_joint_plugin.so" name="mimic_robotiq_140_4">
            <joint>finger_joint</joint>
            <mimicJoint>right_outer_knuckle_joint</mimicJoint>
            <multiplier>-1.0</multiplier>
        </plugin>
        <plugin filename="libroboticsgroup_gazebo_mimic_joint_plugin.so" name="mimic_robotiq_140_2">
            <joint>finger_joint</joint>
            <mimicJoint>left_inner_finger_joint</mimicJoint>
            <multiplier>1.0</multiplier>
            <!--<offset>0.0</offset>-->
        </plugin>
        <plugin filename="libroboticsgroup_gazebo_mimic_joint_plugin.so" name="mimic_robotiq_140_1">
            <joint>finger_joint</joint>
            <mimicJoint>right_inner_finger_joint</mimicJoint>
            <multiplier>1.0</multiplier>
        </plugin>
        <plugin filename="libroboticsgroup_gazebo_mimic_joint_plugin.so" name="mimic_robotiq_140_3">
            <joint>finger_joint</joint>
            <mimicJoint>left_inner_knuckle_joint</mimicJoint>
            <multiplier>-1.0</multiplier>
        </plugin>
        <plugin filename="libroboticsgroup_gazebo_mimic_joint_plugin.so" name="mimic_robotiq_140_5">
            <joint>finger_joint</joint>
            <mimicJoint>right_inner_knuckle_joint</mimicJoint>
            <multiplier>-1.0</multiplier>
        </plugin>
    </gazebo>
    <joint name="base_coupling" type="fixed">
        <origin rpy="0 0 0" xyz="0 0 0"/>
        <parent link="robotiq_arg2f_coupling"/>
        <child link="robotiq_arg2f_base_link"/>
    </joint>
   <link name="panda_grasptarget">
     <inertial>
      <origin rpy="0 0 0" xyz="0 0 0"/>
       <mass value="0.0"/>
       <inertia ixx="0.1" ixy="0" ixz="0" iyy="0.1" iyz="0" izz="0.1"/>
    </inertial>
   </link>
   <joint name="panda_grasptarget_hand" type="fixed">
    <parent link="robotiq_arg2f_coupling"/>
    <child link="panda_grasptarget"/>
    <origin rpy="0 0 0" xyz="0 0 0.23"/>
  </joint>
</robot>
